Workbook

Sheet PORTADA
D4: INFORME GESTIÓN INBOUND
D9: DATOS INFORMATIVOS:
D10: TIPO DE INFORME: | H10: FACTURACIÓN
D11: ENTIDAD | H11: LUCHA CAMPESINA
D12: DESDE: | H12: =MIN('REPORTE GERENCIAL'!C:C) -> 46082
D13: HASTA: | H13: =MAX('REPORTE GERENCIAL'!C:C) -> 46112
E16: CONTENIDO DEL INFORME:
E17: INFORME DE LLAMADAS INBOUND LUCHA CAMPESINA
E18: RESUMEN DE GESTIÓN INBOUND LUCHA CAMPESINA

Sheet REPORTE GERENCIAL
D3: =+PORTADA!D4 -> INFORME GESTIÓN INBOUND
D6: TIPO DE INFORME: | G6: MENSUAL
D7: INSTITUCIÓN: | G7: LUCHA CAMPESINA
D8: DESDE: | G8: =+MIN(C14:C44) -> 46082
D9: HASTA: | G9: =+MAX(C15:C45) -> 46112
C12: LÍNEA ATENCIÓN INBOUND
C13: Fecha | D13: Llamadas entrantes | E13: Llamadas Contestadas | F13: Llamadas fantasma | G13: Llamadas Recuperadas | H13: Llamadas de Seguimiento | I13: Llamadas Abandonadas | J13: Nivel de servicio (SVL) | K13: Nivel de Abandono
C14: 46082 | D14: 0 | E14: 0 | F14: 0 | G14: =+COUNTIFS(TRX!B:B,C14,TRX!F:F,"Recuperada") -> 0 | H14: =+COUNTIFS(TRX!B:B,C14,TRX!F:F,"Seguimiento") -> 0 | I14: 0 | J14: 0% | K14: 0%
C15: 46083 | D15: 1 | E15: 1 | F15: 0 | G15: =+COUNTIFS(TRX!B:B,C15,TRX!F:F,"Recuperada") -> 1 | H15: =+COUNTIFS(TRX!B:B,C15,TRX!F:F,"Seguimiento") -> 0 | I15: 0 | J15: 100% | K15: 0%
C16: 46084 | D16: 1 | E16: 1 | F16: 0 | G16: =+COUNTIFS(TRX!B:B,C16,TRX!F:F,"Recuperada") -> 0 | H16: =+COUNTIFS(TRX!B:B,C16,TRX!F:F,"Seguimiento") -> 0 | I16: 0 | J16: 100% | K16: 0%
C17: 46085 | D17: 0 | E17: 0 | F17: 0 | G17: =+COUNTIFS(TRX!B:B,C17,TRX!F:F,"Recuperada") -> 0 | H17: =+COUNTIFS(TRX!B:B,C17,TRX!F:F,"Seguimiento") -> 0 | I17: 0 | J17: 0% | K17: 0%
C18: 46086 | D18: 0 | E18: 0 | F18: 0 | G18: =+COUNTIFS(TRX!B:B,C18,TRX!F:F,"Recuperada") -> 0 | H18: =+COUNTIFS(TRX!B:B,C18,TRX!F:F,"Seguimiento") -> 0 | I18: 0 | J18: 0% | K18: 0%
C19: 46087 | D19: 2 | E19: 2 | F19: 0 | G19: =+COUNTIFS(TRX!B:B,C19,TRX!F:F,"Recuperada") -> 0 | H19: =+COUNTIFS(TRX!B:B,C19,TRX!F:F,"Seguimiento") -> 0 | I19: 0 | J19: 100% | K19: 0%
C20: 46088 | D20: 1 | E20: 1 | F20: 0 | G20: =+COUNTIFS(TRX!B:B,C20,TRX!F:F,"Recuperada") -> 0 | H20: =+COUNTIFS(TRX!B:B,C20,TRX!F:F,"Seguimiento") -> 0 | I20: 0 | J20: 100% | K20: 0%
C21: 46089 | D21: 0 | E21: 0 | F21: 0 | G21: =+COUNTIFS(TRX!B:B,C21,TRX!F:F,"Recuperada") -> 0 | H21: =+COUNTIFS(TRX!B:B,C21,TRX!F:F,"Seguimiento") -> 0 | I21: 0 | J21: 0% | K21: 0%
C22: 46090 | D22: 0 | E22: 0 | F22: 0 | G22: =+COUNTIFS(TRX!B:B,C22,TRX!F:F,"Recuperada") -> 0 | H22: =+COUNTIFS(TRX!B:B,C22,TRX!F:F,"Seguimiento") -> 0 | I22: 0 | J22: 0% | K22: 0%
C23: 46091 | D23: 2 | E23: 2 | F23: 0 | G23: =+COUNTIFS(TRX!B:B,C23,TRX!F:F,"Recuperada") -> 0 | H23: =+COUNTIFS(TRX!B:B,C23,TRX!F:F,"Seguimiento") -> 0 | I23: 0 | J23: 100% | K23: 0%
C24: 46092 | D24: 1 | E24: 1 | F24: 0 | G24: =+COUNTIFS(TRX!B:B,C24,TRX!F:F,"Recuperada") -> 0 | H24: =+COUNTIFS(TRX!B:B,C24,TRX!F:F,"Seguimiento") -> 0 | I24: 0 | J24: 100% | K24: 0%
C25: 46093 | D25: 2 | E25: 2 | F25: 0 | G25: =+COUNTIFS(TRX!B:B,C25,TRX!F:F,"Recuperada") -> 0 | H25: =+COUNTIFS(TRX!B:B,C25,TRX!F:F,"Seguimiento") -> 0 | I25: 0 | J25: 100% | K25: 0%
... C44: 46112 | D44: 5 | E44: 4 | F44: 0 | G44: =+COUNTIFS(TRX!B:B,C44,TRX!F:F,"Recuperada") -> 0 | H44: =+COUNTIFS(TRX!B:B,C44,TRX!F:F,"Seguimiento") -> 0 | I44: 1 | J44: 80% | K44: 20%
C45: Total del reporte: | D45: 40 | E45: 36 | F45: 1 | G45: =+SUM(G14:G44) -> 1 | H45: =+SUM(H14:H44) -> 0 | I45: 4 | J45: 90% | K45: 10%

Sheet TRX
A4: REGISTRO DE LLAMADAS DEL MES
A13: USUARIO/AGENTE | B13: FECHA DE LLAMADA | C13: HORA DE LLAMADA | D13: HORA DE FIN | E13: TMO | F13: ESTADO DE LA LLAMADA | G13: NUMERO DE CEDULA | H13: APELLIDOS Y NOMBRES | I13: CIUDAD | J13: TELEFONO DE CONTACTO | K13: CELULAR DE CONTACTO | L13: CORREO | M13: ESTADO DEL CLIENTE | N13: MOTIVO DE LLAMADA | O13: SUBMOTIVO | P13: OBSERVACIONES | Q13: CANALES DE COMUNICACIÓN
A14: Bballadares7 | B14: 46082 | C14: 2026-03-01 06:44:35 | D14: 2026-03-01 06:53:11 | E14: 2026-03-01 06:53:11 | F14: Atendida | G14: 0999999999 | H14: Sin nombres | I14: No aplica | J14: 022222222 | K14: 0999999999 | L14: noaplica@kimobill.com | M14: Titular | N14: MONITOREO DEL SERVICIO | O14: LLAMADA DE PRUEBA | P14: Llamada de prueba | Q14: Inbound
A15: Gfigueroa1 | B15: 46083 | C15: 2026-03-02 09:22:43 | D15: 2026-03-02 09:25:09 | E15: 2026-03-02 09:25:09 | F15: Recuperada | G15: 1717449167 | H15: CELI ESPIN GABRIELA ALEXANDRA | I15: NO APLICA | K15: 0987357124 | M15: Titular | N15: INFORMACIÓN GENERAL | O15: CONTACTO PARA AGENCIAS | P15: Se le está verificando la información y colgó la comunicación. | Q15: Inbound
A16: Gfigueroa1 | B16: 46083 | C16: 2026-03-02 09:27:28 | D16: 2026-03-02 09:28:51 | E16: 2026-03-02 09:28:51 | F16: Atendida | G16: 1717449167 | H16: CELI ESPIN GABRIELA ALEXANDRA | I16: NO APLICA | K16: 0987357124 | M16: Titular | N16: INFORMACIÓN GENERAL | O16: CONTACTO PARA PROPUESTAS | P16: Se le menciona el correo de propuesta. | Q16: Inbound
A17: Ahernandez1 | B17: 46083 | C17: 2026-03-02 18:59:44 | D17: 2026-03-02 19:02:17 | E17: 2026-03-02 19:02:17 | F17: Atendida | G17: 0953285608 | H17: VITE BARCO JOSEPH ANTHONY | I17: Milagro | K17: 0962270923 | M17: Titular | N17: INFORMACIÓN GENERAL | O17: INFORMACIÓN DE SERVICIOS | P17: Se informa a socio acercarse a la agencia para conocer las cuotas de su crédito. | Q17: Inbound
A18: Bballadares7 | B18: 46084 | C18: 2026-03-03 02:12:12 | D18: 2026-03-03 02:21:18 | E18: 2026-03-03 02:21:18 | F18: Atendida | G18: 0999999999 | H18: Sin nombres | I18: No aplica | J18: 022222222 | K18: 0999999999 | L18: noaplica@kimobill.com | M18: Titular | N18: MONITOREO DEL SERVICIO | O18: LLAMADA DE PRUEBA | P18: Llamada de prueba | Q18: Inbound
A19: Otorres1 | B19: 46084 | C19: 2026-03-03 08:44:53 | D19: 2026-03-03 08:51:09 | E19: 2026-03-03 08:51:09 | F19: Atendida | G19: 1717449167 | H19: CELI ESPIN GABRIELA ALEXANDRA | I19: QUITO | J19: 020000000 | K19: 0987357124 | L19: noaplica@kimobill.com | M19: Titular | N19: INFORMACIÓN GENERAL | O19: CORREO ELECTRÓNICO DE FUNCIONARIOS | P19: Se entrega correo de propuestas. | Q19: Inbound
A20: Vtoapanta1 | B20: 46084 | C20: 2026-03-03 11:14:35 | D20: 2026-03-03 11:16:41 | E20: 2026-03-03 11:16:41 | F20: Atendida | G20: 1750705681 | H20: ZUMBA MEJIA INDIRA DELIA | I20: QUITO | J20: 020000000 | K20: 0979270518 | L20: noaplica@kimobill.com | M20: Titular | N20: INFORMACIÓN GENERAL | O20: EXTENSIONES DE FUNCIONARIOS | P20: Se menciona que puede comunicarse con los asesores en horario laboral | Q20: Inbound
A21: Ltisalema2 | B21: 46084 | C21: 2026-03-03 15:53:13 | D21: 2026-03-03 15:55:00 | E21: 2026-03-03 15:55:00 | F21: Atendida | G21: 1750705681 | H21: ZUMBA MEJIA INDIRA DELIA | I21: QUITO | J21: 020000000 | K21: 0979270518 | L21: noaplica@kimobill.com | M21: Titular | N21: INFORMACIÓN GENERAL | O21: CONTACTO PARA AGENCIAS | P21: Contacto de agencias | Q21: Inbound
A22: Dlara1 | B22: 46085 | C22: 2026-03-04 09:48:32 | D22: 2026-03-04 09:57:29 | E22: 2026-03-04 09:57:29 | F22: Atendida | G22: 0920332939 | H22: GUADALUPE CARRIEL RAUL ALBERTO | I22: NO APLICA | J22: 020000000 | K22: 0997879510 | L22: rguadalupe@seguroslaunion.com | M22: Titular | N22: INFORMACIÓN GENERAL | O22: CONTACTO PARA AGENCIAS | P22: Información de telefonos de contacto de colaborador. | Q22: Inbound
A23: Tochoa7 | B23: 46085 | C23: 2026-03-04 14:59:01 | D23: 2026-03-04 15:02:47 | E23: 2026-03-04 15:02:47 | F23: Atendida | G23: 0105763262 | H23: BUSTAMANTE SEGARRA VICENTE ALBINO | I23: NO APLICA | K23: 0998211460 | L23: NO APLICA | M23: Titular | N23: INFORMACIÓN GENERAL | O23: CONTACTO PARA AGENCIAS | P23: Se entrega el número de la agencia Cumanda | Q23: Inbound
A24: Cleiva7 | B24: 46085 | C24: 2026-03-04 14:47:25 | D24: 2026-03-04 15:05:13 | E24: 2026-03-04 15:05:13 | F24: Atendida | G24: 0105763262 | H24: BUSTAMANTE SEGARRA VICENTE ALBINO | I24: NO APLICA | J24: 020000000 | K24: 0998211460 | L24: NO APLICA | M24: Titular | N24: INFORMACIÓN GENERAL | O24: EXTENSIONES DE FUNCIONARIOS | P24: Se le brinda la extensión. | Q24: Inbound
A25: Cleiva7 | B25: 46085 | C25: 2026-03-04 15:05:37 | D25: 2026-03-04 15:06:39 | E25: 2026-03-04 15:06:39 | F25: Atendida | G25: 0105763262 | H25: BUSTAMANTE SEGARRA VICENTE ALBINO | I25: NO APLICA | J25: 020000000 | K25: 0998211460 | L25: NO APLICA | M25: Titular | N25: INFORMACIÓN GENERAL | O25: INFORMACIÓN DE SERVICIOS | P25: Se le brinda información sobre servicios. | Q25: Inbound
A26: Husina6 | B26: 46085 | C26: 2026-03-04 16:30:27 | D26: 2026-03-04 16:35:43 | E26: 2026-03-04 16:35:43 | F26: Atendida | G26: 0926146242 | H26: DIAS PEÑAFIEL JOHANNA ELIZABETH | I26: NO APLICA | J26: 020000000 | K26: 0999999999 | L26: noaplica@kimobill.com | M26: Titular | N26: INFORMACIÓN GENERAL | O26: INFORMACION DE BANCA VIRTUAL/APP | P26: Se menciona que se debe acercar a la agencia | Q26: Inbound
A27: Bballadares7 | B27: 46086 | C27: 2026-03-05 01:11:41 | D27: 2026-03-05 06:35:09 | E27: 2026-03-05 06:35:09 | F27: Atendida | G27: 0999999999 | H27: Sin nombres | I27: No aplica | J27: 022222222 | K27: 0999999999 | L27: noaplica@kimobill.com | M27: Titular | N27: MONITOREO DEL SERVICIO | O27: LLAMADA DE PRUEBA | P27: Llamada de prueba | Q27: Inbound
A28: Cleiva7 | B28: 46086 | C28: 2026-03-05 14:30:09 | D28: 2026-03-05 14:33:50 | E28: 2026-03-05 14:33:50 | F28: Atendida | G28: 0955743661 | H28: HURTADO PERALTA DANNY AXEL | I28: NO APLICA | J28: 020000000 | K28: 0993055179 | M28: Titular | N28: INFORMACIÓN GENERAL | O28: CONTACTO PARA AGENCIAS | P28: Se le brinda el contacto de la agencia. | Q28: Inbound
A29: Cleiva7 | B29: 46086 | C29: 2026-03-05 14:33:53 | D29: 2026-03-05 14:35:36 | E29: 2026-03-05 14:35:36 | F29: Atendida | G29: 0955743661 | H29: HURTADO PERALTA DANNY AXEL | I29: NO APLICA | J29: 020000000 | K29: 0993055179 | M29: Titular | N29: INFORMACIÓN GENERAL | O29: INFORMACIÓN DE CRÉDITOS | P29: Se le brinda la informacion sobre créditos. | Q29: Inbound
A30: Cleiva7 | B30: 46086 | C30: 2026-03-05 14:35:38 | D30: 2026-03-05 14:37:52 | E30: 2026-03-05 14:37:52 | F30: Atendida | G30: 0955743661 | H30: HURTADO PERALTA DANNY AXEL | I30: NO APLICA | J30: 020000000 | K30: 0993055179 | M30: Titular | N30: INFORMACIÓN GENERAL | O30: INFORMACIÓN DE SERVICIOS | P30: Se le brinda la información sobre servicios. | Q30: Inbound
A31: Tochoa7 | B31: 46087 | C31: 2026-03-06 08:05:08 | D31: 2026-03-06 08:07:04 | E31: 2026-03-06 08:07:04 | F31: Atendida | G31: 1206407924 | H31: GALECIO VILLEGAS ADRIANA MARGARITA | I31: NO APLICA | K31: 0980341685 | L31: NO APLICA | M31: Titular | N31: INFORMACIÓN GENERAL | O31: INFORMACIÓN DE CRÉDITOS | P31: Se entrega información para la pre cancelación del crédito | Q31: Inbound
A32: Jguacho1 | B32: 46088 | C32: 2026-03-07 08:32:41 | D32: 2026-03-07 08:36:54 | E32: 2026-03-07 08:36:54 | F32: Atendida | G32: 0928993492 | H32: ESPINOZA RIVERA DIANA GUADALUPE | I32: CUENCA | K32: 0969271914 | M32: Titular | N32: INFORMACIÓN GENERAL | O32: INFORMACIÓN APP | P32: Se le menciona cómo puede verificar el número de cuenta | Q32: Inbound
A33: Otorres1 | B33: 46088 | C33: 2026-03-07 18:24:52 | D33: 2026-03-07 18:33:23 | E33: 2026-03-07 18:33:23 | F33: Atendida | G33: 0940607815 | H33: VALLE PALAGUACHI THALYA VICTORIA | I33: EL TRIUNFO | J33: 020000000 | K33: 0990864061 | L33: noaplica@kimobill.com | M33: Titular | N33: INFORMACIÓN GENERAL | O33: CUENTAS DE AHORRO | P33: Se indica que para su requerimiento debe acercarse a la agencia. | Q33: Inbound
A34: Rmejia1 | B34: 46089 | C34: 2026-03-08 16:55:29 | D34: 2026-03-08 16:57:12 | E34: 2026-03-08 16:57:12 | F34: Atendida | G34: 0931956924 | H34: CARRASCO PERALTA GINGER ZULAY | I34: NO APLICA | J34: 020000000 | K34: 0982556321 | L34: noaplica@kimobill.com | M34: Titular | N34: CALIDAD DE LLAMADA | O34: LLAMADA CORTADA | P34: Llamada cortada | Q34: Inbound
A35: Otorres1 | B35: 46089 | C35: 2026-03-08 17:00:03 | D35: 2026-03-08 17:01:48 | E35: 2026-03-08 17:01:48 | F35: Atendida | G35: 0931956924 | H35: CARRASCO PERALTA GINGER ZULAY | I35: NO APLICA | J35: 020000000 | K35: 0982556321 | L35: noaplica@kimobill.com | M35: Titular | N35: INFORMACIÓN GENERAL | O35: INFORMACION DE TRANSFERENCIAS | P35: Se corta la llamada no se realiza el proceso. | Q35: Inbound
A36: Tochoa7 | B36: 46090 | C36: 2026-03-09 12:51:42 | D36: 2026-03-09 12:51:51 | E36: 2026-03-09 12:51:51 | F36: Atendida | G36: 0912546090 | H36: NICOLA VELASQUEZ BRENDA ALICIA | I36: NO APLICA | K36: 0997929634 | L36: NO APLICA | M36: Titular | N36: INFORMACIÓN GENERAL | O36: CUENTAS DE AHORRO | P36: Se entrega información y requisitos para el cierre de cuenta | Q36: Inbound
A37: Tochoa7 | B37: 46090 | C37: 2026-03-09 12:48:52 | D37: 2026-03-09 12:51:03 | E37: 2026-03-09 12:51:03 | F37: Atendida | G37: 0912546090 | H37: NICOLA VELASQUEZ BRENDA ALICIA | I37: NO APLICA | K37: 0997929634 | L37: NO APLICA | M37: Titular | N37: INFORMACIÓN GENERAL | O37: CONTACTO PARA AGENCIAS | P37: Se entrega contacto de agencia | Q37: Inbound
A38: Gfigueroa1 | B38: 46090 | C38: 2026-03-09 15:12:09 | D38: 2026-03-09 15:18:25 | E38: 2026-03-09 15:18:25 | F38: Atendida | G38: 0927843631 | H38: RUIZ ABARCA JOSE FRANCISCO | I38: NO APLICA | K38: 0982805505 | M38: Titular | N38: INFORMACIÓN GENERAL | O38: CUENTAS DE AHORRO PROGRAMADO | P38: Información del ahorro programado. | Q38: Inbound
A39: Gfigueroa1 | B39: 46090 | C39: 2026-03-09 15:18:12 | D39: 2026-03-09 15:18:56 | E39: 2026-03-09 15:18:56 | F39: Atendida | G39: 0927843631 | H39: RUIZ ABARCA JOSE FRANCISCO | I39: NO APLICA | K39: 0982805505 | M39: Titular | N39: INFORMACIÓN GENERAL | O39: INFORMACIÓN DE CRÉDITOS | P39: Información del pago del crédito. | Q39: Inbound
A40: Dlara1 | B40: 46091 | C40: 2026-03-10 10:07:39 | D40: 2026-03-10 10:14:59 | E40: 2026-03-10 10:14:59 | F40: Atendida | G40: 0401363981 | H40: BENAVIDES NARVAEZ DIEGO GERMAN | I40: QUITO | K40: 0999999999 | M40: Titular | N40: INFORMACIÓN GENERAL | O40: CONTACTO PARA AGENCIAS | P40: Información de contacto de agencia. | Q40: Inbound
A41: Ltisalema2 | B41: 46092 | C41: 2026-03-11 06:15:35 | D41: 2026-03-11 06:26:43 | E41: 2026-03-11 06:26:43 | F41: Atendida | G41: 0999999999 | H41: Sin nombres | I41: No aplica | J41: 022222222 | K41: 0999999999 | L41: noaplica@kimobill.com | M41: Titular | N41: MONITOREO DEL SERVICIO | O41: LLAMADA DE PRUEBA | P41: Llamada de prueba | Q41: Inbound
A42: Dcevallos1 | B42: 46093 | C42: 2026-03-12 06:09:00 | D42: 2026-03-12 06:10:22 | E42: 2026-03-12 06:10:22 | F42: Atendida | G42: 0999999999 | H42: Sin nombres | I42: No aplica | J42: 022222222 | K42: 0964256168 | L42: noaplica@kimobill.com | M42: Titular | N42: MONITOREO DEL SERVICIO | O42: LLAMADA DE PRUEBA | P42: Llamada de prueba. | Q42: Inbound
A43: Macaro1 | B43: 46093 | C43: 2026-03-12 12:55:12 | D43: 2026-03-12 12:57:06 | E43: 2026-03-12 12:57:06 | F43: Atendida | G43: 9999999999 | H43: Sin nombres | I43: No aplica | J43: 022222222 | K43: 0999999999 | L43: noaplica@kimobill.com | M43: Titular | N43: CALIDAD DE LLAMADA | O43: LLAMADA DE PRUEBA | P43: Llamada de prueba | Q43: Inbound
A44: Ahernandez1 | B44: 46093 | C44: 2026-03-12 12:57:36 | D44: 2026-03-12 12:57:59 | E44: 2026-03-12 12:57:59 | F44: Atendida | G44: 0999999999 | H44: Sin nombres | I44: No aplica | J44: 022222222 | K44: 0999999999 | L44: noaplica@kimobill.com | M44: Titular | N44: CALIDAD DE LLAMADA | O44: LLAMADA DE PRUEBA | P44: Llamada de prueba. | Q44: Inbound
A45: Ltisalema2 | B45: 46094 | C45: 2026-03-13 05:42:57 | D45: 2026-03-13 05:53:26 | E45: 2026-03-13 05:53:26 | F45: Atendida | G45: 0999999999 | H45: Sin nombres | I45: No aplica | J45: 022222222 | K45: 0999999999 | L45: noaplica@kimobill.com | M45: Titular | N45: MONITOREO DEL SERVICIO | O45: LLAMADA DE PRUEBA | P45: Llamada de prueba | Q45: Inbound
A46: Jgallardo2 | B46: 46094 | C46: 2026-03-13 11:16:32 | D46: 2026-03-13 11:24:11 | E46: 2026-03-13 11:24:11 | F46: Atendida | G46: 0350006664 | H46: ORTEGA MONTOYA EMILY ANTONIETA | I46: AZOGUES | K46: 0968386664 | L46: emi182105@hotmail.com | M46: Titular | N46: QUEJAS | O46: POR EL CREDITO | P46: Se ingresa PQRS exitosamente. | Q46: Inbound
A47: Vtoapanta1 | B47: 46095 | C47: 2026-03-14 02:13:32 | D47: 2026-03-14 02:14:22 | E47: 2026-03-14 02:14:22 | F47: Atendida | G47: 0999999999 | H47: Sin nombres | I47: No aplica | J47: 022222222 | K47: 0999999999 | L47: noaplica@kimobill.com | M47: Titular | N47: CALIDAD DE LLAMADA | O47: LLAMADA DE PRUEBA | P47: Prueba | Q47: Inbound
A48: Tochoa7 | B48: 46096 | C48: 2026-03-15 06:33:01 | D48: 2026-03-15 06:34:57 | E48: 2026-03-15 06:34:57 | F48: Atendida | G48: 0999999999 | H48: Sin nombres | I48: No aplica | J48: 022222222 | K48: 0999999999 | L48: noaplica@kimobill.com | M48: Titular | N48: MONITOREO DEL SERVICIO | O48: LLAMADA DE PRUEBA | P48: Llamada de prueba | Q48: Inbound
A49: Husina6 | B49: 46096 | C49: 2026-03-15 12:34:06 | D49: 2026-03-15 13:10:35 | E49: 2026-03-15 13:10:35 | F49: Atendida | G49: 1720807468 | H49: BARRAGAN MACIAS MARIA BELEN | I49: No aplica | J49: 020000000 | K49: 0991093134 | L49: noaplica@kimobill.com | M49: Titular | N49: INFORMACIÓN GENERAL | O49: INFORMACIÓN DE SERVICIOS | P49: Información de servivios funerarios | Q49: Inbound
A50: Dmunoz9 | B50: 46096 | C50: 2026-03-15 14:02:38 | D50: 2026-03-15 14:04:25 | E50: 2026-03-15 14:04:25 | F50: Atendida | G50: 0999999999 | H50: Sin nombres | I50: NO APLICA | J50: 020000000 | K50: 0999999999 | L50: noaplica@kimobill.com | M50: Titular | N50: CALIDAD DE LLAMADA | O50: LLAMADA CORTADA | P50: Socio corta la llamada | Q50: Inbound
A51: Dmunoz9 | B51: 46096 | C51: 2026-03-15 14:04:33 | D51: 2026-03-15 14:08:20 | E51: 2026-03-15 14:08:20 | F51: Atendida | G51: 1720807468 | H51: BARRAGAN MACIAS MARIA BELEN | I51: NO APLICA | J51: 020000000 | K51: 0991093134 | L51: noaplica@kimobill.com | M51: Titular | N51: INFORMACIÓN GENERAL | O51: INFORMACIÓN DE SERVICIOS | P51: se direcciona a socia para que se comunique con servicios de la cooperativa para servicios exequial | Q51: Inbound
...

Sheet RESUMEN DE GESTION
C3: RESUMEN DE GESTION MES
C9: MOTIVO DE LA LLAMADA | D9: TOTAL | E9: % | G9: CANAL DE COMUNICACIÓN | H9: TOTAL | I9: %
C10: QUEJAS | D10: 1 | E10: 0.018867925 | G10: Inbound | H10: 53 | I10: 1
C11: POR EL CREDITO | D11: 1 | E11: 0.018867925 | G11: Total general | H11: 53 | I11: 1
C12: MONITOREO DEL SERVICIO | D12: 9 | E12: 0.16981132
C13: LLAMADA DE PRUEBA | D13: 9 | E13: 0.16981132
C14: INFORMACIÓN GENERAL | D14: 28 | E14: 0.52830189
C15: INFORMACION DE TRANSFERENCIAS | D15: 1 | E15: 0.018867925
C16: CUENTAS DE AHORRO PROGRAMADO | D16: 1 | E16: 0.018867925
C17: INFORMACIÓN DE CRÉDITOS | D17: 3 | E17: 0.056603774
C18: INFORMACIÓN APP | D18: 2 | E18: 0.037735849
C19: INFORMACIÓN DE SERVICIOS | D19: 5 | E19: 0.094339623
C20: CONTACTO PARA AGENCIAS | D20: 7 | E20: 0.13207547
C21: CONTACTO PARA PROPUESTAS | D21: 1 | E21: 0.018867925
C22: CORREO ELECTRÓNICO DE FUNCIONARIOS | D22: 1 | E22: 0.018867925
C23: EXTENSIONES DE FUNCIONARIOS | D23: 2 | E23: 0.037735849
... C29: Total general | D29: 53 | E29: 1

Sheet RESUMEN GLOBAL
C3: RESUMEN DE LLAMADAS DEL MES
C12: MOTIVO LLAMADA (TRX) | D12: TOTAL | E12: %
C13: CALIDAD DE LLAMADA | D13: 15 | E13: 0.28301887
C14: INFORMACIÓN GENERAL | D14: 28 | E14: 0.52830189
C15: MONITOREO DEL SERVICIO | D15: 9 | E15: 0.16981132
C16: QUEJAS | D16: 1 | E16: 0.018867925
C17: Total general | D17: 53 | E17: 1
C33: SUB MOTIVO LLAMADA (TRX) | D33: TOTAL | E33: %
C34: LLAMADA CORTADA | D34: 5 | E34: 0.094339623
C35: LLAMADA DE PRUEBA | D35: 19 | E35: 0.35849057
C36: INFORMACION DE TRANSFERENCIAS | D36: 1 | E36: 0.018867925
C37: CUENTAS DE AHORRO PROGRAMADO | D37: 1 | E37: 0.018867925
C38: INFORMACIÓN DE CRÉDITOS | D38: 3 | E38: 0.056603774
C39: INFORMACIÓN APP | D39: 2 | E39: 0.037735849
C40: INFORMACIÓN DE SERVICIOS | D40: 5 | E40: 0.094339623
C41: CONTACTO PARA AGENCIAS | D41: 7 | E41: 0.13207547
C42: CONTACTO PARA PROPUESTAS | D42: 1 | E42: 0.018867925
C43: CORREO ELECTRÓNICO DE FUNCIONARIOS | D43: 1 | E43: 0.018867925
C44: EXTENSIONES DE FUNCIONARIOS | D44: 2 | E44: 0.037735849
C45: INFORMACION DE BANCA VIRTUAL/APP | D45: 1 | E45: 0.018867925
... C48: Total general | D48: 53 | E48: 1

Sheet LLAMADAS DIARIAS
C3: COMPARATIVO LLAMADAS CONTESTADAS Y ABANDONADAS
A7: Etiquetas de fila | B7: Número de Llamadas entrantes | C7: Número de Llamadas Abandonadas
A8: 46082 | B8: 0 | C8: 0
A9: 46083 | B9: 1 | C9: 0
A10: 46084 | B10: 1 | C10: 0
A11: 46085 | B11: 0 | C11: 0
A12: 46086 | B12: 0 | C12: 0
A13: 46087 | B13: 2 | C13: 0
A14: 46088 | B14: 1 | C14: 0
A15: 46089 | B15: 0 | C15: 0
A16: 46090 | B16: 0 | C16: 0
A17: 46091 | B17: 2 | C17: 0
A18: 46092 | B18: 1 | C18: 0
A19: 46093 | B19: 2 | C19: 0
... A38: 46112 | B38: 5 | C38: 1
A39: Total general | B39: 40 | C39: 4

Sheet GESTION IVR
B1: IVR
